Traceback (most recent call last):
  File "traceStack.py", line 3, in <module>
    raise Exception("err1")
Exception: err1
